[19/Jan/2022 19:56:20] INFO [django.utils.autoreload:617] Watching for file changes with StatReloader
[19/Jan/2022 19:56:20] INFO [django.utils.autoreload:617] Watching for file changes with StatReloader
[19/Jan/2022 19:56:24] INFO [django.server:157] "GET /application/address HTTP/1.1" 200 9835
[19/Jan/2022 19:56:24] INFO [django.server:157] "GET /application/address HTTP/1.1" 200 9835
[19/Jan/2022 19:56:30] INFO [django.server:157] "POST /application/address HTTP/1.1" 302 0
[19/Jan/2022 19:56:30] INFO [django.server:157] "POST /application/address HTTP/1.1" 302 0
[19/Jan/2022 19:56:31] ERROR [django.request:224] Internal Server Error: /application/addressCorrection
Traceback (most recent call last):
  File "C:\Users\JAndr\AppData\Local\Packages\PythonSoftwareFoundation.Python.3.9_qbz5n2kfra8p0\LocalCache\local-packages\Python39\site-packages\django\core\handlers\exception.py", line 47, in inner
    response = get_response(request)
  File "C:\Users\JAndr\AppData\Local\Packages\PythonSoftwareFoundation.Python.3.9_qbz5n2kfra8p0\LocalCache\local-packages\Python39\site-packages\django\core\handlers\base.py", line 181, in _get_response
    response = wrapped_callback(request, *callback_args, **callback_kwargs)
  File "C:\Users\JAndr\OneDrive\Projects\GetYourConnexion\DigitalEquity_MobileVers\mobileVers\application\views.py", line 318, in addressCorrection
    dict_address = validateUSPS(q)
  File "C:\Users\JAndr\OneDrive\Projects\GetYourConnexion\DigitalEquity_MobileVers\mobileVers\application\backend.py", line 341, in validateUSPS
    validation = usps.validate_address(address)
  File "C:\Users\JAndr\AppData\Local\Packages\PythonSoftwareFoundation.Python.3.9_qbz5n2kfra8p0\LocalCache\local-packages\Python39\site-packages\usps\usps.py", line 43, in validate_address
    return AddressValidate(self, *args, **kwargs)
  File "C:\Users\JAndr\AppData\Local\Packages\PythonSoftwareFoundation.Python.3.9_qbz5n2kfra8p0\LocalCache\local-packages\Python39\site-packages\usps\usps.py", line 59, in __init__
    self.result = usps.send_request('validate', xml)
  File "C:\Users\JAndr\AppData\Local\Packages\PythonSoftwareFoundation.Python.3.9_qbz5n2kfra8p0\LocalCache\local-packages\Python39\site-packages\usps\usps.py", line 39, in send_request
    raise USPSApiError(response['Error']['Description'])
usps.usps.USPSApiError: XML Syntax Error: Please check the XML request to see if it can be parsed.(B)
[19/Jan/2022 19:56:31] ERROR [django.request:224] Internal Server Error: /application/addressCorrection
Traceback (most recent call last):
  File "C:\Users\JAndr\AppData\Local\Packages\PythonSoftwareFoundation.Python.3.9_qbz5n2kfra8p0\LocalCache\local-packages\Python39\site-packages\django\core\handlers\exception.py", line 47, in inner
    response = get_response(request)
  File "C:\Users\JAndr\AppData\Local\Packages\PythonSoftwareFoundation.Python.3.9_qbz5n2kfra8p0\LocalCache\local-packages\Python39\site-packages\django\core\handlers\base.py", line 181, in _get_response
    response = wrapped_callback(request, *callback_args, **callback_kwargs)
  File "C:\Users\JAndr\OneDrive\Projects\GetYourConnexion\DigitalEquity_MobileVers\mobileVers\application\views.py", line 318, in addressCorrection
    dict_address = validateUSPS(q)
  File "C:\Users\JAndr\OneDrive\Projects\GetYourConnexion\DigitalEquity_MobileVers\mobileVers\application\backend.py", line 341, in validateUSPS
    validation = usps.validate_address(address)
  File "C:\Users\JAndr\AppData\Local\Packages\PythonSoftwareFoundation.Python.3.9_qbz5n2kfra8p0\LocalCache\local-packages\Python39\site-packages\usps\usps.py", line 43, in validate_address
    return AddressValidate(self, *args, **kwargs)
  File "C:\Users\JAndr\AppData\Local\Packages\PythonSoftwareFoundation.Python.3.9_qbz5n2kfra8p0\LocalCache\local-packages\Python39\site-packages\usps\usps.py", line 59, in __init__
    self.result = usps.send_request('validate', xml)
  File "C:\Users\JAndr\AppData\Local\Packages\PythonSoftwareFoundation.Python.3.9_qbz5n2kfra8p0\LocalCache\local-packages\Python39\site-packages\usps\usps.py", line 39, in send_request
    raise USPSApiError(response['Error']['Description'])
usps.usps.USPSApiError: XML Syntax Error: Please check the XML request to see if it can be parsed.(B)
[19/Jan/2022 19:56:31] ERROR [django.server:157] "GET /application/addressCorrection HTTP/1.1" 500 90718
[19/Jan/2022 19:56:31] ERROR [django.server:157] "GET /application/addressCorrection HTTP/1.1" 500 90718
[19/Jan/2022 19:57:49] INFO [django.utils.autoreload:240] C:\Users\JAndr\OneDrive\Projects\GetYourConnexion\DigitalEquity_MobileVers\mobileVers\application\views.py changed, reloading.
[19/Jan/2022 19:57:49] INFO [django.utils.autoreload:240] C:\Users\JAndr\OneDrive\Projects\GetYourConnexion\DigitalEquity_MobileVers\mobileVers\application\views.py changed, reloading.
